Workbook

Sheet Pricing and editable planning i
A1: Pricing and editable planning inputs
A2: NaukriShield — Business Plan · Main Scenario
A4: Variable / dimension | B4: Value
A5: Student monthly free allowance | B5: =3 -> 3
A6: Cafe monthly price | B6: =499 -> 499
A7: API check price | B7: =49 -> 49
A8: Haiku cost per check | B8: =0.75 -> 0.75
A9: Cached data cost per check | B9: =1.5 -> 1.5
A10: Cost per check | B10: ='Pricing and editable planning i'!B8+'Pricing and editable planning i'!B9 -> 2.25
A11: Paying cafes | B11: =200 -> 200
A12: Year 1 API checks | B12: =30000 -> 30000
A13: Checks per cafe per month | B13: =10 -> 10
A14: Active free students | B14: =1000 -> 1000
A15: Checks per free student per month | B15: =3 -> 3
A16: Monthly non-check overhead | B16: =14692.5 -> 14692.5
A17: Opening cash assumption | B17: =300000 -> 300000

Sheet Year 1 totals and 45-cafe break
A1: Year 1 totals and 45-cafe break-even
A2: NaukriShield — Business Plan · Main Scenario
A4: Variable / dimension | B4: Value
A5: NS Year 1 revenue | B5: =SUM('Monthly revenue and check costs'!B5,'Monthly revenue and check costs'!C5,'Monthly revenue and check costs'!D5,'Monthly revenue and check costs'!E5,'Monthly revenue and check costs'!F5,'Monthly revenue and check costs'!G5,'Monthly revenue and check costs'!H5,'Monthly revenue and check costs'!I5,'Monthly revenue and check costs'!J5,'Monthly revenue and check costs'!K5,'Monthly revenue and check costs'!L5,'Monthly revenue and check costs'!M5) -> 2667600
A6: NS Year 1 check costs | B6: =SUM('Monthly revenue and check costs'!B13,'Monthly revenue and check costs'!C13,'Monthly revenue and check costs'!D13,'Monthly revenue and check costs'!E13,'Monthly revenue and check costs'!F13,'Monthly revenue and check costs'!G13,'Monthly revenue and check costs'!H13,'Monthly revenue and check costs'!I13,'Monthly revenue and check costs'!J13,'Monthly revenue and check costs'!K13,'Monthly revenue and check costs'!L13,'Monthly revenue and check costs'!M13) -> 202500
A7: NS Year 1 gross margin | B7: =IFERROR(('Year 1 totals and 45-cafe break'!B5-'Year 1 totals and 45-cafe break'!B6)/'Year 1 totals and 45-cafe break'!B5,"") -> 0.92408907
A8: NS Year 1 operating profit | B8: =SUM('Runway and operating profit'!B10,'Runway and operating profit'!C10,'Runway and operating profit'!D10,'Runway and operating profit'!E10,'Runway and operating profit'!F10,'Runway and operating profit'!G10,'Runway and operating profit'!H10,'Runway and operating profit'!I10,'Runway and operating profit'!J10,'Runway and operating profit'!K10,'Runway and operating profit'!L10,'Runway and operating profit'!M10) -> 2288790
A9: NS cafe contribution | B9: ='Pricing and editable planning i'!B6-'Pricing and editable planning i'!B13*'Pricing and editable planning i'!B10 -> 476.5
A10: NS free monthly subsidy | B10: ='Pricing and editable planning i'!B14*MIN('Pricing and editable planning i'!B15,'Pricing and editable planning i'!B5)*'Pricing and editable planning i'!B10 -> 6750
A11: NS cafe-only break-even count | B11: =IF(IF(IF(ISERROR('Year 1 totals and 45-cafe break'!B9>0),'Year 1 totals and 45-cafe break'!B9>0,IF('Year 1 totals and 45-cafe break'!B9="","",'Year 1 totals and 45-cafe break'!B9>0))="",FALSE,IF(ISERROR('Year 1 totals and 45-cafe break'!B9>0),'Year 1 totals and 45-cafe break'!B9>0,IF('Year 1 totals and 45-cafe break'!B9="","",'Year 1 totals and 45-cafe break'!B9>0))),CEILING(('Pricing and editable planning i'!B16+'Year 1 totals and 45-cafe break'!B10)/'Year 1 totals and 45-cafe break'!B9,1),"") -> 45
A12: NS break-even count with API | B12: =IF(IF(IF(ISERROR('Year 1 totals and 45-cafe break'!B9>0),'Year 1 totals and 45-cafe break'!B9>0,IF('Year 1 totals and 45-cafe break'!B9="","",'Year 1 totals and 45-cafe break'!B9>0))="",FALSE,IF(ISERROR('Year 1 totals and 45-cafe break'!B9>0),'Year 1 totals and 45-cafe break'!B9>0,IF('Year 1 totals and 45-cafe break'!B9="","",'Year 1 totals and 45-cafe break'!B9>0))),CEILING(MAX(0,'Pricing and editable planning i'!B16+'Year 1 totals and 45-cafe break'!B10-'Pricing and editable planning i'!B12/12*('Pricing and editable planning i'!B7-'Pricing and editable planning i'!B10))/'Year 1 totals and 45-cafe break'!B9,1),"") -> 0
A13: NS 45-cafe profit without API | B13: =45*'Year 1 totals and 45-cafe break'!B9-'Year 1 totals and 45-cafe break'!B10-'Pricing and editable planning i'!B16 -> 0
A14: NS cafe check-cost-only limit | B14: ='Pricing and editable planning i'!B6/'Pricing and editable planning i'!B10 -> 221.77778
A15: NS starting cash runway months | B15: =IF(IF(IF(ISERROR('Year 1 totals and 45-cafe break'!B8<0),'Year 1 totals and 45-cafe break'!B8<0,IF('Year 1 totals and 45-cafe break'!B8="","",'Year 1 totals and 45-cafe break'!B8<0))="",FALSE,IF(ISERROR('Year 1 totals and 45-cafe break'!B8<0),'Year 1 totals and 45-cafe break'!B8<0,IF('Year 1 totals and 45-cafe break'!B8="","",'Year 1 totals and 45-cafe break'!B8<0))),'Pricing and editable planning i'!B17/(-'Year 1 totals and 45-cafe break'!B8/12),"")

Sheet Monthly revenue and check costs
A1: Monthly revenue and check costs
A2: NaukriShield — Business Plan · Main Scenario
A4: Variable / dimension | B4: 2026-11 | C4: 2026-12 | D4: 2027-01 | E4: 2027-02 | F4: 2027-03 | G4: 2027-04 | H4: 2027-05 | I4: 2027-06 | J4: 2027-07 | K4: 2027-08 | L4: 2027-09 | M4: 2027-10
A5: NS revenue | B5: =SUM('Monthly revenue and check costs'!B6,'Monthly revenue and check costs'!B7,'Monthly revenue and check costs'!B8) -> 222300 | C5: =SUM('Monthly revenue and check costs'!C6,'Monthly revenue and check costs'!C7,'Monthly revenue and check costs'!C8) -> 222300 | D5: =SUM('Monthly revenue and check costs'!D6,'Monthly revenue and check costs'!D7,'Monthly revenue and check costs'!D8) -> 222300 | E5: =SUM('Monthly revenue and check costs'!E6,'Monthly revenue and check costs'!E7,'Monthly revenue and check costs'!E8) -> 222300 | F5: =SUM('Monthly revenue and check costs'!F6,'Monthly revenue and check costs'!F7,'Monthly revenue and check costs'!F8) -> 222300 | G5: =SUM('Monthly revenue and check costs'!G6,'Monthly revenue and check costs'!G7,'Monthly revenue and check costs'!G8) -> 222300 | H5: =SUM('Monthly revenue and check costs'!H6,'Monthly revenue and check costs'!H7,'Monthly revenue and check costs'!H8) -> 222300 | I5: =SUM('Monthly revenue and check costs'!I6,'Monthly revenue and check costs'!I7,'Monthly revenue and check costs'!I8) -> 222300 | ... M5: =SUM('Monthly revenue and check costs'!M6,'Monthly revenue and check costs'!M7,'Monthly revenue and check costs'!M8) -> 222300
A6: API | B6: =IF(EXACT("API","Cyber-cafes"),'Pricing and editable planning i'!B11*'Pricing and editable planning i'!B6,IF(EXACT("API","API"),'Pricing and editable planning i'!B12/12*'Pricing and editable planning i'!B7,0)) -> 122500 | C6: =IF(EXACT("API","Cyber-cafes"),'Pricing and editable planning i'!B11*'Pricing and editable planning i'!B6,IF(EXACT("API","API"),'Pricing and editable planning i'!B12/12*'Pricing and editable planning i'!B7,0)) -> 122500 | D6: =IF(EXACT("API","Cyber-cafes"),'Pricing and editable planning i'!B11*'Pricing and editable planning i'!B6,IF(EXACT("API","API"),'Pricing and editable planning i'!B12/12*'Pricing and editable planning i'!B7,0)) -> 122500 | E6: =IF(EXACT("API","Cyber-cafes"),'Pricing and editable planning i'!B11*'Pricing and editable planning i'!B6,IF(EXACT("API","API"),'Pricing and editable planning i'!B12/12*'Pricing and editable planning i'!B7,0)) -> 122500 | F6: =IF(EXACT("API","Cyber-cafes"),'Pricing and editable planning i'!B11*'Pricing and editable planning i'!B6,IF(EXACT("API","API"),'Pricing and editable planning i'!B12/12*'Pricing and editable planning i'!B7,0)) -> 122500 | G6: =IF(EXACT("API","Cyber-cafes"),'Pricing and editable planning i'!B11*'Pricing and editable planning i'!B6,IF(EXACT("API","API"),'Pricing and editable planning i'!B12/12*'Pricing and editable planning i'!B7,0)) -> 122500 | H6: =IF(EXACT("API","Cyber-cafes"),'Pricing and editable planning i'!B11*'Pricing and editable planning i'!B6,IF(EXACT("API","API"),'Pricing and editable planning i'!B12/12*'Pricing and editable planning i'!B7,0)) -> 122500 | I6: =IF(EXACT("API","Cyber-cafes"),'Pricing and editable planning i'!B11*'Pricing and editable planning i'!B6,IF(EXACT("API","API"),'Pricing and editable planning i'!B12/12*'Pricing and editable planning i'!B7,0)) -> 122500 | J6: =IF(EXACT("API","Cyber-cafes"),'Pricing and editable planning i'!B11*'Pricing and editable planning i'!B6,IF(EXACT("API","API"),'Pricing and editable planning i'!B12/12*'Pricing and editable planning i'!B7,0)) -> 122500 | K6: =IF(EXACT("API","Cyber-cafes"),'Pricing and editable planning i'!B11*'Pricing and editable planning i'!B6,IF(EXACT("API","API"),'Pricing and editable planning i'!B12/12*'Pricing and editable planning i'!B7,0)) -> 122500 | L6: =IF(EXACT("API","Cyber-cafes"),'Pricing and editable planning i'!B11*'Pricing and editable planning i'!B6,IF(EXACT("API","API"),'Pricing and editable planning i'!B12/12*'Pricing and editable planning i'!B7,0)) -> 122500 | M6: =IF(EXACT("API","Cyber-cafes"),'Pricing and editable planning i'!B11*'Pricing and editable planning i'!B6,IF(EXACT("API","API"),'Pricing and editable planning i'!B12/12*'Pricing and editable planning i'!B7,0)) -> 122500
A7: Cyber-cafes | B7: =IF(EXACT("Cyber-cafes","Cyber-cafes"),'Pricing and editable planning i'!B11*'Pricing and editable planning i'!B6,IF(EXACT("Cyber-cafes","API"),'Pricing and editable planning i'!B12/12*'Pricing and editable planning i'!B7,0)) -> 99800 | C7: =IF(EXACT("Cyber-cafes","Cyber-cafes"),'Pricing and editable planning i'!B11*'Pricing and editable planning i'!B6,IF(EXACT("Cyber-cafes","API"),'Pricing and editable planning i'!B12/12*'Pricing and editable planning i'!B7,0)) -> 99800 | D7: =IF(EXACT("Cyber-cafes","Cyber-cafes"),'Pricing and editable planning i'!B11*'Pricing and editable planning i'!B6,IF(EXACT("Cyber-cafes","API"),'Pricing and editable planning i'!B12/12*'Pricing and editable planning i'!B7,0)) -> 99800 | E7: =IF(EXACT("Cyber-cafes","Cyber-cafes"),'Pricing and editable planning i'!B11*'Pricing and editable planning i'!B6,IF(EXACT("Cyber-cafes","API"),'Pricing and editable planning i'!B12/12*'Pricing and editable planning i'!B7,0)) -> 99800 | F7: =IF(EXACT("Cyber-cafes","Cyber-cafes"),'Pricing and editable planning i'!B11*'Pricing and editable planning i'!B6,IF(EXACT("Cyber-cafes","API"),'Pricing and editable planning i'!B12/12*'Pricing and editable planning i'!B7,0)) -> 99800 | G7: =IF(EXACT("Cyber-cafes","Cyber-cafes"),'Pricing and editable planning i'!B11*'Pricing and editable planning i'!B6,IF(EXACT("Cyber-cafes","API"),'Pricing and editable planning i'!B12/12*'Pricing and editable planning i'!B7,0)) -> 99800 | H7: =IF(EXACT("Cyber-cafes","Cyber-cafes"),'Pricing and editable planning i'!B11*'Pricing and editable planning i'!B6,IF(EXACT("Cyber-cafes","API"),'Pricing and editable planning i'!B12/12*'Pricing and editable planning i'!B7,0)) -> 99800 | I7: =IF(EXACT("Cyber-cafes","Cyber-cafes"),'Pricing and editable planning i'!B11*'Pricing and editable planning i'!B6,IF(EXACT("Cyber-cafes","API"),'Pricing and editable planning i'!B12/12*'Pricing and editable planning i'!B7,0)) -> 99800 | J7: =IF(EXACT("Cyber-cafes","Cyber-cafes"),'Pricing and editable planning i'!B11*'Pricing and editable planning i'!B6,IF(EXACT("Cyber-cafes","API"),'Pricing and editable planning i'!B12/12*'Pricing and editable planning i'!B7,0)) -> 99800 | K7: =IF(EXACT("Cyber-cafes","Cyber-cafes"),'Pricing and editable planning i'!B11*'Pricing and editable planning i'!B6,IF(EXACT("Cyber-cafes","API"),'Pricing and editable planning i'!B12/12*'Pricing and editable planning i'!B7,0)) -> 99800 | L7: =IF(EXACT("Cyber-cafes","Cyber-cafes"),'Pricing and editable planning i'!B11*'Pricing and editable planning i'!B6,IF(EXACT("Cyber-cafes","API"),'Pricing and editable planning i'!B12/12*'Pricing and editable planning i'!B7,0)) -> 99800 | M7: =IF(EXACT("Cyber-cafes","Cyber-cafes"),'Pricing and editable planning i'!B11*'Pricing and editable planning i'!B6,IF(EXACT("Cyber-cafes","API"),'Pricing and editable planning i'!B12/12*'Pricing and editable planning i'!B7,0)) -> 99800
A8: Students | B8: =IF(EXACT("Students","Cyber-cafes"),'Pricing and editable planning i'!B11*'Pricing and editable planning i'!B6,IF(EXACT("Students","API"),'Pricing and editable planning i'!B12/12*'Pricing and editable planning i'!B7,0)) -> 0 | C8: =IF(EXACT("Students","Cyber-cafes"),'Pricing and editable planning i'!B11*'Pricing and editable planning i'!B6,IF(EXACT("Students","API"),'Pricing and editable planning i'!B12/12*'Pricing and editable planning i'!B7,0)) -> 0 | D8: =IF(EXACT("Students","Cyber-cafes"),'Pricing and editable planning i'!B11*'Pricing and editable planning i'!B6,IF(EXACT("Students","API"),'Pricing and editable planning i'!B12/12*'Pricing and editable planning i'!B7,0)) -> 0 | E8: =IF(EXACT("Students","Cyber-cafes"),'Pricing and editable planning i'!B11*'Pricing and editable planning i'!B6,IF(EXACT("Students","API"),'Pricing and editable planning i'!B12/12*'Pricing and editable planning i'!B7,0)) -> 0 | F8: =IF(EXACT("Students","Cyber-cafes"),'Pricing and editable planning i'!B11*'Pricing and editable planning i'!B6,IF(EXACT("Students","API"),'Pricing and editable planning i'!B12/12*'Pricing and editable planning i'!B7,0)) -> 0 | G8: =IF(EXACT("Students","Cyber-cafes"),'Pricing and editable planning i'!B11*'Pricing and editable planning i'!B6,IF(EXACT("Students","API"),'Pricing and editable planning i'!B12/12*'Pricing and editable planning i'!B7,0)) -> 0 | H8: =IF(EXACT("Students","Cyber-cafes"),'Pricing and editable planning i'!B11*'Pricing and editable planning i'!B6,IF(EXACT("Students","API"),'Pricing and editable planning i'!B12/12*'Pricing and editable planning i'!B7,0)) -> 0 | I8: =IF(EXACT("Students","Cyber-cafes"),'Pricing and editable planning i'!B11*'Pricing and editable planning i'!B6,IF(EXACT("Students","API"),'Pricing and editable planning i'!B12/12*'Pricing and editable planning i'!B7,0)) -> 0 | J8: =IF(EXACT("Students","Cyber-cafes"),'Pricing and editable planning i'!B11*'Pricing and editable planning i'!B6,IF(EXACT("Students","API"),'Pricing and editable planning i'!B12/12*'Pricing and editable planning i'!B7,0)) -> 0 | K8: =IF(EXACT("Students","Cyber-cafes"),'Pricing and editable planning i'!B11*'Pricing and editable planning i'!B6,IF(EXACT("Students","API"),'Pricing and editable planning i'!B12/12*'Pricing and editable planning i'!B7,0)) -> 0 | L8: =IF(EXACT("Students","Cyber-cafes"),'Pricing and editable planning i'!B11*'Pricing and editable planning i'!B6,IF(EXACT("Students","API"),'Pricing and editable planning i'!B12/12*'Pricing and editable planning i'!B7,0)) -> 0 | M8: =IF(EXACT("Students","Cyber-cafes"),'Pricing and editable planning i'!B11*'Pricing and editable planning i'!B6,IF(EXACT("Students","API"),'Pricing and editable planning i'!B12/12*'Pricing and editable planning i'!B7,0)) -> 0
A9: NS checks | B9: =SUM('Monthly revenue and check costs'!B10,'Monthly revenue and check costs'!B11,'Monthly revenue and check costs'!B12) -> 7500 | C9: =SUM('Monthly revenue and check costs'!C10,'Monthly revenue and check costs'!C11,'Monthly revenue and check costs'!C12) -> 7500 | D9: =SUM('Monthly revenue and check costs'!D10,'Monthly revenue and check costs'!D11,'Monthly revenue and check costs'!D12) -> 7500 | E9: =SUM('Monthly revenue and check costs'!E10,'Monthly revenue and check costs'!E11,'Monthly revenue and check costs'!E12) -> 7500 | F9: =SUM('Monthly revenue and check costs'!F10,'Monthly revenue and check costs'!F11,'Monthly revenue and check costs'!F12) -> 7500 | G9: =SUM('Monthly revenue and check costs'!G10,'Monthly revenue and check costs'!G11,'Monthly revenue and check costs'!G12) -> 7500 | H9: =SUM('Monthly revenue and check costs'!H10,'Monthly revenue and check costs'!H11,'Monthly revenue and check costs'!H12) -> 7500 | I9: =SUM('Monthly revenue and check costs'!I10,'Monthly revenue and check costs'!I11,'Monthly revenue and check costs'!I12) -> 7500 | ... M9: =SUM('Monthly revenue and check costs'!M10,'Monthly revenue and check costs'!M11,'Monthly revenue and check costs'!M12) -> 7500
A10: API | B10: =IF(EXACT("API","Cyber-cafes"),'Pricing and editable planning i'!B11*'Pricing and editable planning i'!B13,IF(EXACT("API","API"),'Pricing and editable planning i'!B12/12,'Pricing and editable planning i'!B14*MIN('Pricing and editable planning i'!B15,'Pricing and editable planning i'!B5))) -> 2500 | C10: =IF(EXACT("API","Cyber-cafes"),'Pricing and editable planning i'!B11*'Pricing and editable planning i'!B13,IF(EXACT("API","API"),'Pricing and editable planning i'!B12/12,'Pricing and editable planning i'!B14*MIN('Pricing and editable planning i'!B15,'Pricing and editable planning i'!B5))) -> 2500 | D10: =IF(EXACT("API","Cyber-cafes"),'Pricing and editable planning i'!B11*'Pricing and editable planning i'!B13,IF(EXACT("API","API"),'Pricing and editable planning i'!B12/12,'Pricing and editable planning i'!B14*MIN('Pricing and editable planning i'!B15,'Pricing and editable planning i'!B5))) -> 2500 | E10: =IF(EXACT("API","Cyber-cafes"),'Pricing and editable planning i'!B11*'Pricing and editable planning i'!B13,IF(EXACT("API","API"),'Pricing and editable planning i'!B12/12,'Pricing and editable planning i'!B14*MIN('Pricing and editable planning i'!B15,'Pricing and editable planning i'!B5))) -> 2500 | F10: =IF(EXACT("API","Cyber-cafes"),'Pricing and editable planning i'!B11*'Pricing and editable planning i'!B13,IF(EXACT("API","API"),'Pricing and editable planning i'!B12/12,'Pricing and editable planning i'!B14*MIN('Pricing and editable planning i'!B15,'Pricing and editable planning i'!B5))) -> 2500 | G10: =IF(EXACT("API","Cyber-cafes"),'Pricing and editable planning i'!B11*'Pricing and editable planning i'!B13,IF(EXACT("API","API"),'Pricing and editable planning i'!B12/12,'Pricing and editable planning i'!B14*MIN('Pricing and editable planning i'!B15,'Pricing and editable planning i'!B5))) -> 2500 | H10: =IF(EXACT("API","Cyber-cafes"),'Pricing and editable planning i'!B11*'Pricing and editable planning i'!B13,IF(EXACT("API","API"),'Pricing and editable planning i'!B12/12,'Pricing and editable planning i'!B14*MIN('Pricing and editable planning i'!B15,'Pricing and editable planning i'!B5))) -> 2500 | I10: =IF(EXACT("API","Cyber-cafes"),'Pricing and editable planning i'!B11*'Pricing and editable planning i'!B13,IF(EXACT("API","API"),'Pricing and editable planning i'!B12/12,'Pricing and editable planning i'!B14*MIN('Pricing and editable planning i'!B15,'Pricing and editable planning i'!B5))) -> 2500 | J10: =IF(EXACT("API","Cyber-cafes"),'Pricing and editable planning i'!B11*'Pricing and editable planning i'!B13,IF(EXACT("API","API"),'Pricing and editable planning i'!B12/12,'Pricing and editable planning i'!B14*MIN('Pricing and editable planning i'!B15,'Pricing and editable planning i'!B5))) -> 2500 | K10: =IF(EXACT("API","Cyber-cafes"),'Pricing and editable planning i'!B11*'Pricing and editable planning i'!B13,IF(EXACT("API","API"),'Pricing and editable planning i'!B12/12,'Pricing and editable planning i'!B14*MIN('Pricing and editable planning i'!B15,'Pricing and editable planning i'!B5))) -> 2500 | L10: =IF(EXACT("API","Cyber-cafes"),'Pricing and editable planning i'!B11*'Pricing and editable planning i'!B13,IF(EXACT("API","API"),'Pricing and editable planning i'!B12/12,'Pricing and editable planning i'!B14*MIN('Pricing and editable planning i'!B15,'Pricing and editable planning i'!B5))) -> 2500 | M10: =IF(EXACT("API","Cyber-cafes"),'Pricing and editable planning i'!B11*'Pricing and editable planning i'!B13,IF(EXACT("API","API"),'Pricing and editable planning i'!B12/12,'Pricing and editable planning i'!B14*MIN('Pricing and editable planning i'!B15,'Pricing and editable planning i'!B5))) -> 2500
A11: Cyber-cafes | B11: =IF(EXACT("Cyber-cafes","Cyber-cafes"),'Pricing and editable planning i'!B11*'Pricing and editable planning i'!B13,IF(EXACT("Cyber-cafes","API"),'Pricing and editable planning i'!B12/12,'Pricing and editable planning i'!B14*MIN('Pricing and editable planning i'!B15,'Pricing and editable planning i'!B5))) -> 2000 | C11: =IF(EXACT("Cyber-cafes","Cyber-cafes"),'Pricing and editable planning i'!B11*'Pricing and editable planning i'!B13,IF(EXACT("Cyber-cafes","API"),'Pricing and editable planning i'!B12/12,'Pricing and editable planning i'!B14*MIN('Pricing and editable planning i'!B15,'Pricing and editable planning i'!B5))) -> 2000 | D11: =IF(EXACT("Cyber-cafes","Cyber-cafes"),'Pricing and editable planning i'!B11*'Pricing and editable planning i'!B13,IF(EXACT("Cyber-cafes","API"),'Pricing and editable planning i'!B12/12,'Pricing and editable planning i'!B14*MIN('Pricing and editable planning i'!B15,'Pricing and editable planning i'!B5))) -> 2000 | E11: =IF(EXACT("Cyber-cafes","Cyber-cafes"),'Pricing and editable planning i'!B11*'Pricing and editable planning i'!B13,IF(EXACT("Cyber-cafes","API"),'Pricing and editable planning i'!B12/12,'Pricing and editable planning i'!B14*MIN('Pricing and editable planning i'!B15,'Pricing and editable planning i'!B5))) -> 2000 | F11: =IF(EXACT("Cyber-cafes","Cyber-cafes"),'Pricing and editable planning i'!B11*'Pricing and editable planning i'!B13,IF(EXACT("Cyber-cafes","API"),'Pricing and editable planning i'!B12/12,'Pricing and editable planning i'!B14*MIN('Pricing and editable planning i'!B15,'Pricing and editable planning i'!B5))) -> 2000 | G11: =IF(EXACT("Cyber-cafes","Cyber-cafes"),'Pricing and editable planning i'!B11*'Pricing and editable planning i'!B13,IF(EXACT("Cyber-cafes","API"),'Pricing and editable planning i'!B12/12,'Pricing and editable planning i'!B14*MIN('Pricing and editable planning i'!B15,'Pricing and editable planning i'!B5))) -> 2000 | H11: =IF(EXACT("Cyber-cafes","Cyber-cafes"),'Pricing and editable planning i'!B11*'Pricing and editable planning i'!B13,IF(EXACT("Cyber-cafes","API"),'Pricing and editable planning i'!B12/12,'Pricing and editable planning i'!B14*MIN('Pricing and editable planning i'!B15,'Pricing and editable planning i'!B5))) -> 2000 | I11: =IF(EXACT("Cyber-cafes","Cyber-cafes"),'Pricing and editable planning i'!B11*'Pricing and editable planning i'!B13,IF(EXACT("Cyber-cafes","API"),'Pricing and editable planning i'!B12/12,'Pricing and editable planning i'!B14*MIN('Pricing and editable planning i'!B15,'Pricing and editable planning i'!B5))) -> 2000 | J11: =IF(EXACT("Cyber-cafes","Cyber-cafes"),'Pricing and editable planning i'!B11*'Pricing and editable planning i'!B13,IF(EXACT("Cyber-cafes","API"),'Pricing and editable planning i'!B12/12,'Pricing and editable planning i'!B14*MIN('Pricing and editable planning i'!B15,'Pricing and editable planning i'!B5))) -> 2000 | K11: =IF(EXACT("Cyber-cafes","Cyber-cafes"),'Pricing and editable planning i'!B11*'Pricing and editable planning i'!B13,IF(EXACT("Cyber-cafes","API"),'Pricing and editable planning i'!B12/12,'Pricing and editable planning i'!B14*MIN('Pricing and editable planning i'!B15,'Pricing and editable planning i'!B5))) -> 2000 | L11: =IF(EXACT("Cyber-cafes","Cyber-cafes"),'Pricing and editable planning i'!B11*'Pricing and editable planning i'!B13,IF(EXACT("Cyber-cafes","API"),'Pricing and editable planning i'!B12/12,'Pricing and editable planning i'!B14*MIN('Pricing and editable planning i'!B15,'Pricing and editable planning i'!B5))) -> 2000 | M11: =IF(EXACT("Cyber-cafes","Cyber-cafes"),'Pricing and editable planning i'!B11*'Pricing and editable planning i'!B13,IF(EXACT("Cyber-cafes","API"),'Pricing and editable planning i'!B12/12,'Pricing and editable planning i'!B14*MIN('Pricing and editable planning i'!B15,'Pricing and editable planning i'!B5))) -> 2000
A12: Students | B12: =IF(EXACT("Students","Cyber-cafes"),'Pricing and editable planning i'!B11*'Pricing and editable planning i'!B13,IF(EXACT("Students","API"),'Pricing and editable planning i'!B12/12,'Pricing and editable planning i'!B14*MIN('Pricing and editable planning i'!B15,'Pricing and editable planning i'!B5))) -> 3000 | C12: =IF(EXACT("Students","Cyber-cafes"),'Pricing and editable planning i'!B11*'Pricing and editable planning i'!B13,IF(EXACT("Students","API"),'Pricing and editable planning i'!B12/12,'Pricing and editable planning i'!B14*MIN('Pricing and editable planning i'!B15,'Pricing and editable planning i'!B5))) -> 3000 | D12: =IF(EXACT("Students","Cyber-cafes"),'Pricing and editable planning i'!B11*'Pricing and editable planning i'!B13,IF(EXACT("Students","API"),'Pricing and editable planning i'!B12/12,'Pricing and editable planning i'!B14*MIN('Pricing and editable planning i'!B15,'Pricing and editable planning i'!B5))) -> 3000 | E12: =IF(EXACT("Students","Cyber-cafes"),'Pricing and editable planning i'!B11*'Pricing and editable planning i'!B13,IF(EXACT("Students","API"),'Pricing and editable planning i'!B12/12,'Pricing and editable planning i'!B14*MIN('Pricing and editable planning i'!B15,'Pricing and editable planning i'!B5))) -> 3000 | F12: =IF(EXACT("Students","Cyber-cafes"),'Pricing and editable planning i'!B11*'Pricing and editable planning i'!B13,IF(EXACT("Students","API"),'Pricing and editable planning i'!B12/12,'Pricing and editable planning i'!B14*MIN('Pricing and editable planning i'!B15,'Pricing and editable planning i'!B5))) -> 3000 | G12: =IF(EXACT("Students","Cyber-cafes"),'Pricing and editable planning i'!B11*'Pricing and editable planning i'!B13,IF(EXACT("Students","API"),'Pricing and editable planning i'!B12/12,'Pricing and editable planning i'!B14*MIN('Pricing and editable planning i'!B15,'Pricing and editable planning i'!B5))) -> 3000 | H12: =IF(EXACT("Students","Cyber-cafes"),'Pricing and editable planning i'!B11*'Pricing and editable planning i'!B13,IF(EXACT("Students","API"),'Pricing and editable planning i'!B12/12,'Pricing and editable planning i'!B14*MIN('Pricing and editable planning i'!B15,'Pricing and editable planning i'!B5))) -> 3000 | I12: =IF(EXACT("Students","Cyber-cafes"),'Pricing and editable planning i'!B11*'Pricing and editable planning i'!B13,IF(EXACT("Students","API"),'Pricing and editable planning i'!B12/12,'Pricing and editable planning i'!B14*MIN('Pricing and editable planning i'!B15,'Pricing and editable planning i'!B5))) -> 3000 | J12: =IF(EXACT("Students","Cyber-cafes"),'Pricing and editable planning i'!B11*'Pricing and editable planning i'!B13,IF(EXACT("Students","API"),'Pricing and editable planning i'!B12/12,'Pricing and editable planning i'!B14*MIN('Pricing and editable planning i'!B15,'Pricing and editable planning i'!B5))) -> 3000 | K12: =IF(EXACT("Students","Cyber-cafes"),'Pricing and editable planning i'!B11*'Pricing and editable planning i'!B13,IF(EXACT("Students","API"),'Pricing and editable planning i'!B12/12,'Pricing and editable planning i'!B14*MIN('Pricing and editable planning i'!B15,'Pricing and editable planning i'!B5))) -> 3000 | L12: =IF(EXACT("Students","Cyber-cafes"),'Pricing and editable planning i'!B11*'Pricing and editable planning i'!B13,IF(EXACT("Students","API"),'Pricing and editable planning i'!B12/12,'Pricing and editable planning i'!B14*MIN('Pricing and editable planning i'!B15,'Pricing and editable planning i'!B5))) -> 3000 | M12: =IF(EXACT("Students","Cyber-cafes"),'Pricing and editable planning i'!B11*'Pricing and editable planning i'!B13,IF(EXACT("Students","API"),'Pricing and editable planning i'!B12/12,'Pricing and editable planning i'!B14*MIN('Pricing and editable planning i'!B15,'Pricing and editable planning i'!B5))) -> 3000
A13: NS check costs | B13: =SUM('Monthly revenue and check costs'!B14,'Monthly revenue and check costs'!B15,'Monthly revenue and check costs'!B16) -> 16875 | C13: =SUM('Monthly revenue and check costs'!C14,'Monthly revenue and check costs'!C15,'Monthly revenue and check costs'!C16) -> 16875 | D13: =SUM('Monthly revenue and check costs'!D14,'Monthly revenue and check costs'!D15,'Monthly revenue and check costs'!D16) -> 16875 | E13: =SUM('Monthly revenue and check costs'!E14,'Monthly revenue and check costs'!E15,'Monthly revenue and check costs'!E16) -> 16875 | F13: =SUM('Monthly revenue and check costs'!F14,'Monthly revenue and check costs'!F15,'Monthly revenue and check costs'!F16) -> 16875 | G13: =SUM('Monthly revenue and check costs'!G14,'Monthly revenue and check costs'!G15,'Monthly revenue and check costs'!G16) -> 16875 | H13: =SUM('Monthly revenue and check costs'!H14,'Monthly revenue and check costs'!H15,'Monthly revenue and check costs'!H16) -> 16875 | I13: =SUM('Monthly revenue and check costs'!I14,'Monthly revenue and check costs'!I15,'Monthly revenue and check costs'!I16) -> 16875 | ... M13: =SUM('Monthly revenue and check costs'!M14,'Monthly revenue and check costs'!M15,'Monthly revenue and check costs'!M16) -> 16875
A14: API | B14: ='Monthly revenue and check costs'!B10*'Pricing and editable planning i'!B10 -> 5625 | C14: ='Monthly revenue and check costs'!C10*'Pricing and editable planning i'!B10 -> 5625 | D14: ='Monthly revenue and check costs'!D10*'Pricing and editable planning i'!B10 -> 5625 | E14: ='Monthly revenue and check costs'!E10*'Pricing and editable planning i'!B10 -> 5625 | F14: ='Monthly revenue and check costs'!F10*'Pricing and editable planning i'!B10 -> 5625 | G14: ='Monthly revenue and check costs'!G10*'Pricing and editable planning i'!B10 -> 5625 | H14: ='Monthly revenue and check costs'!H10*'Pricing and editable planning i'!B10 -> 5625 | I14: ='Monthly revenue and check costs'!I10*'Pricing and editable planning i'!B10 -> 5625 | J14: ='Monthly revenue and check costs'!J10*'Pricing and editable planning i'!B10 -> 5625 | K14: ='Monthly revenue and check costs'!K10*'Pricing and editable planning i'!B10 -> 5625 | L14: ='Monthly revenue and check costs'!L10*'Pricing and editable planning i'!B10 -> 5625 | M14: ='Monthly revenue and check costs'!M10*'Pricing and editable planning i'!B10 -> 5625
A15: Cyber-cafes | B15: ='Monthly revenue and check costs'!B11*'Pricing and editable planning i'!B10 -> 4500 | C15: ='Monthly revenue and check costs'!C11*'Pricing and editable planning i'!B10 -> 4500 | D15: ='Monthly revenue and check costs'!D11*'Pricing and editable planning i'!B10 -> 4500 | E15: ='Monthly revenue and check costs'!E11*'Pricing and editable planning i'!B10 -> 4500 | F15: ='Monthly revenue and check costs'!F11*'Pricing and editable planning i'!B10 -> 4500 | G15: ='Monthly revenue and check costs'!G11*'Pricing and editable planning i'!B10 -> 4500 | H15: ='Monthly revenue and check costs'!H11*'Pricing and editable planning i'!B10 -> 4500 | I15: ='Monthly revenue and check costs'!I11*'Pricing and editable planning i'!B10 -> 4500 | J15: ='Monthly revenue and check costs'!J11*'Pricing and editable planning i'!B10 -> 4500 | K15: ='Monthly revenue and check costs'!K11*'Pricing and editable planning i'!B10 -> 4500 | L15: ='Monthly revenue and check costs'!L11*'Pricing and editable planning i'!B10 -> 4500 | M15: ='Monthly revenue and check costs'!M11*'Pricing and editable planning i'!B10 -> 4500
A16: Students | B16: ='Monthly revenue and check costs'!B12*'Pricing and editable planning i'!B10 -> 6750 | C16: ='Monthly revenue and check costs'!C12*'Pricing and editable planning i'!B10 -> 6750 | D16: ='Monthly revenue and check costs'!D12*'Pricing and editable planning i'!B10 -> 6750 | E16: ='Monthly revenue and check costs'!E12*'Pricing and editable planning i'!B10 -> 6750 | F16: ='Monthly revenue and check costs'!F12*'Pricing and editable planning i'!B10 -> 6750 | G16: ='Monthly revenue and check costs'!G12*'Pricing and editable planning i'!B10 -> 6750 | H16: ='Monthly revenue and check costs'!H12*'Pricing and editable planning i'!B10 -> 6750 | I16: ='Monthly revenue and check costs'!I12*'Pricing and editable planning i'!B10 -> 6750 | J16: ='Monthly revenue and check costs'!J12*'Pricing and editable planning i'!B10 -> 6750 | K16: ='Monthly revenue and check costs'!K12*'Pricing and editable planning i'!B10 -> 6750 | L16: ='Monthly revenue and check costs'!L12*'Pricing and editable planning i'!B10 -> 6750 | M16: ='Monthly revenue and check costs'!M12*'Pricing and editable planning i'!B10 -> 6750

Sheet Runway and operating profit
A1: Runway and operating profit
A2: NaukriShield — Business Plan · Main Scenario
A4: Variable / dimension | B4: 2026-11 | C4: 2026-12 | D4: 2027-01 | E4: 2027-02 | F4: 2027-03 | G4: 2027-04 | H4: 2027-05 | I4: 2027-06 | J4: 2027-07 | K4: 2027-08 | L4: 2027-09 | M4: 2027-10
A5: NS revenue | B5: =SUM('Monthly revenue and check costs'!B6,'Monthly revenue and check costs'!B7,'Monthly revenue and check costs'!B8) -> 222300 | C5: =SUM('Monthly revenue and check costs'!C6,'Monthly revenue and check costs'!C7,'Monthly revenue and check costs'!C8) -> 222300 | D5: =SUM('Monthly revenue and check costs'!D6,'Monthly revenue and check costs'!D7,'Monthly revenue and check costs'!D8) -> 222300 | E5: =SUM('Monthly revenue and check costs'!E6,'Monthly revenue and check costs'!E7,'Monthly revenue and check costs'!E8) -> 222300 | F5: =SUM('Monthly revenue and check costs'!F6,'Monthly revenue and check costs'!F7,'Monthly revenue and check costs'!F8) -> 222300 | G5: =SUM('Monthly revenue and check costs'!G6,'Monthly revenue and check costs'!G7,'Monthly revenue and check costs'!G8) -> 222300 | H5: =SUM('Monthly revenue and check costs'!H6,'Monthly revenue and check costs'!H7,'Monthly revenue and check costs'!H8) -> 222300 | I5: =SUM('Monthly revenue and check costs'!I6,'Monthly revenue and check costs'!I7,'Monthly revenue and check costs'!I8) -> 222300 | ... M5: =SUM('Monthly revenue and check costs'!M6,'Monthly revenue and check costs'!M7,'Monthly revenue and check costs'!M8) -> 222300
A6: NS check costs | B6: =SUM('Monthly revenue and check costs'!B14,'Monthly revenue and check costs'!B15,'Monthly revenue and check costs'!B16) -> 16875 | C6: =SUM('Monthly revenue and check costs'!C14,'Monthly revenue and check costs'!C15,'Monthly revenue and check costs'!C16) -> 16875 | D6: =SUM('Monthly revenue and check costs'!D14,'Monthly revenue and check costs'!D15,'Monthly revenue and check costs'!D16) -> 16875 | E6: =SUM('Monthly revenue and check costs'!E14,'Monthly revenue and check costs'!E15,'Monthly revenue and check costs'!E16) -> 16875 | F6: =SUM('Monthly revenue and check costs'!F14,'Monthly revenue and check costs'!F15,'Monthly revenue and check costs'!F16) -> 16875 | G6: =SUM('Monthly revenue and check costs'!G14,'Monthly revenue and check costs'!G15,'Monthly revenue and check costs'!G16) -> 16875 | H6: =SUM('Monthly revenue and check costs'!H14,'Monthly revenue and check costs'!H15,'Monthly revenue and check costs'!H16) -> 16875 | I6: =SUM('Monthly revenue and check costs'!I14,'Monthly revenue and check costs'!I15,'Monthly revenue and check costs'!I16) -> 16875 | ... M6: =SUM('Monthly revenue and check costs'!M14,'Monthly revenue and check costs'!M15,'Monthly revenue and check costs'!M16) -> 16875
A7: NS gross profit | B7: ='Runway and operating profit'!B5-'Runway and operating profit'!B6 -> 205425 | C7: ='Runway and operating profit'!C5-'Runway and operating profit'!C6 -> 205425 | D7: ='Runway and operating profit'!D5-'Runway and operating profit'!D6 -> 205425 | E7: ='Runway and operating profit'!E5-'Runway and operating profit'!E6 -> 205425 | F7: ='Runway and operating profit'!F5-'Runway and operating profit'!F6 -> 205425 | G7: ='Runway and operating profit'!G5-'Runway and operating profit'!G6 -> 205425 | H7: ='Runway and operating profit'!H5-'Runway and operating profit'!H6 -> 205425 | I7: ='Runway and operating profit'!I5-'Runway and operating profit'!I6 -> 205425 | ... M7: ='Runway and operating profit'!M5-'Runway and operating profit'!M6 -> 205425
A8: NS gross margin | B8: =IFERROR('Runway and operating profit'!B7/'Runway and operating profit'!B5,"") -> 0.92408907 | C8: =IFERROR('Runway and operating profit'!C7/'Runway and operating profit'!C5,"") -> 0.92408907 | D8: =IFERROR('Runway and operating profit'!D7/'Runway and operating profit'!D5,"") -> 0.92408907 | E8: =IFERROR('Runway and operating profit'!E7/'Runway and operating profit'!E5,"") -> 0.92408907 | F8: =IFERROR('Runway and operating profit'!F7/'Runway and operating profit'!F5,"") -> 0.92408907 | G8: =IFERROR('Runway and operating profit'!G7/'Runway and operating profit'!G5,"") -> 0.92408907 | H8: =IFERROR('Runway and operating profit'!H7/'Runway and operating profit'!H5,"") -> 0.92408907 | I8: =IFERROR('Runway and operating profit'!I7/'Runway and operating profit'!I5,"") -> 0.92408907 | ... M8: =IFERROR('Runway and operating profit'!M7/'Runway and operating profit'!M5,"") -> 0.92408907
A9: NS overhead | B9: =IF('Pricing and editable planning i'!B16="","",'Pricing and editable planning i'!B16) -> 14692.5 | C9: =IF('Pricing and editable planning i'!B16="","",'Pricing and editable planning i'!B16) -> 14692.5 | D9: =IF('Pricing and editable planning i'!B16="","",'Pricing and editable planning i'!B16) -> 14692.5 | E9: =IF('Pricing and editable planning i'!B16="","",'Pricing and editable planning i'!B16) -> 14692.5 | F9: =IF('Pricing and editable planning i'!B16="","",'Pricing and editable planning i'!B16) -> 14692.5 | G9: =IF('Pricing and editable planning i'!B16="","",'Pricing and editable planning i'!B16) -> 14692.5 | H9: =IF('Pricing and editable planning i'!B16="","",'Pricing and editable planning i'!B16) -> 14692.5 | I9: =IF('Pricing and editable planning i'!B16="","",'Pricing and editable planning i'!B16) -> 14692.5 | J9: =IF('Pricing and editable planning i'!B16="","",'Pricing and editable planning i'!B16) -> 14692.5 | K9: =IF('Pricing and editable planning i'!B16="","",'Pricing and editable planning i'!B16) -> 14692.5 | L9: =IF('Pricing and editable planning i'!B16="","",'Pricing and editable planning i'!B16) -> 14692.5 | M9: =IF('Pricing and editable planning i'!B16="","",'Pricing and editable planning i'!B16) -> 14692.5
A10: NS operating profit | B10: ='Runway and operating profit'!B7-'Runway and operating profit'!B9 -> 190732.5 | C10: ='Runway and operating profit'!C7-'Runway and operating profit'!C9 -> 190732.5 | D10: ='Runway and operating profit'!D7-'Runway and operating profit'!D9 -> 190732.5 | E10: ='Runway and operating profit'!E7-'Runway and operating profit'!E9 -> 190732.5 | F10: ='Runway and operating profit'!F7-'Runway and operating profit'!F9 -> 190732.5 | G10: ='Runway and operating profit'!G7-'Runway and operating profit'!G9 -> 190732.5 | H10: ='Runway and operating profit'!H7-'Runway and operating profit'!H9 -> 190732.5 | I10: ='Runway and operating profit'!I7-'Runway and operating profit'!I9 -> 190732.5 | ... M10: ='Runway and operating profit'!M7-'Runway and operating profit'!M9 -> 190732.5
A11: NS opening cash | B11: =IF('Pricing and editable planning i'!B17="","",'Pricing and editable planning i'!B17) -> 300000 | C11: =IF('Runway and operating profit'!B12="","",'Runway and operating profit'!B12) -> 490732.5 | D11: =IF('Runway and operating profit'!C12="","",'Runway and operating profit'!C12) -> 681465 | E11: =IF('Runway and operating profit'!D12="","",'Runway and operating profit'!D12) -> 872197.5 | F11: =IF('Runway and operating profit'!E12="","",'Runway and operating profit'!E12) -> 1062930 | G11: =IF('Runway and operating profit'!F12="","",'Runway and operating profit'!F12) -> 1253662.5 | H11: =IF('Runway and operating profit'!G12="","",'Runway and operating profit'!G12) -> 1444395 | I11: =IF('Runway and operating profit'!H12="","",'Runway and operating profit'!H12) -> 1635127.5 | J11: =IF('Runway and operating profit'!I12="","",'Runway and operating profit'!I12) -> 1825860 | ... M11: =IF('Runway and operating profit'!L12="","",'Runway and operating profit'!L12) -> 2398057.5
A12: NS closing cash | B12: ='Runway and operating profit'!B11+'Runway and operating profit'!B10 -> 490732.5 | C12: ='Runway and operating profit'!C11+'Runway and operating profit'!C10 -> 681465 | D12: ='Runway and operating profit'!D11+'Runway and operating profit'!D10 -> 872197.5 | E12: ='Runway and operating profit'!E11+'Runway and operating profit'!E10 -> 1062930 | F12: ='Runway and operating profit'!F11+'Runway and operating profit'!F10 -> 1253662.5 | G12: ='Runway and operating profit'!G11+'Runway and operating profit'!G10 -> 1444395 | H12: ='Runway and operating profit'!H11+'Runway and operating profit'!H10 -> 1635127.5 | I12: ='Runway and operating profit'!I11+'Runway and operating profit'!I10 -> 1825860 | ... M12: ='Runway and operating profit'!M11+'Runway and operating profit'!M10 -> 2588790
A13: NS monthly burn | B13: =MAX(0,-'Runway and operating profit'!B10) -> 0 | C13: =MAX(0,-'Runway and operating profit'!C10) -> 0 | D13: =MAX(0,-'Runway and operating profit'!D10) -> 0 | E13: =MAX(0,-'Runway and operating profit'!E10) -> 0 | F13: =MAX(0,-'Runway and operating profit'!F10) -> 0 | G13: =MAX(0,-'Runway and operating profit'!G10) -> 0 | H13: =MAX(0,-'Runway and operating profit'!H10) -> 0 | I13: =MAX(0,-'Runway and operating profit'!I10) -> 0 | ... M13: =MAX(0,-'Runway and operating profit'!M10) -> 0
A14: NS cash runway months | B14: =IF(IF(IF(ISERROR('Runway and operating profit'!B13>0),'Runway and operating profit'!B13>0,IF('Runway and operating profit'!B13="","",'Runway and operating profit'!B13>0))="",FALSE,IF(ISERROR('Runway and operating profit'!B13>0),'Runway and operating profit'!B13>0,IF('Runway and operating profit'!B13="","",'Runway and operating profit'!B13>0))),'Runway and operating profit'!B12/'Runway and operating profit'!B13,"") | C14: =IF(IF(IF(ISERROR('Runway and operating profit'!C13>0),'Runway and operating profit'!C13>0,IF('Runway and operating profit'!C13="","",'Runway and operating profit'!C13>0))="",FALSE,IF(ISERROR('Runway and operating profit'!C13>0),'Runway and operating profit'!C13>0,IF('Runway and operating profit'!C13="","",'Runway and operating profit'!C13>0))),'Runway and operating profit'!C12/'Runway and operating profit'!C13,"") | D14: =IF(IF(IF(ISERROR('Runway and operating profit'!D13>0),'Runway and operating profit'!D13>0,IF('Runway and operating profit'!D13="","",'Runway and operating profit'!D13>0))="",FALSE,IF(ISERROR('Runway and operating profit'!D13>0),'Runway and operating profit'!D13>0,IF('Runway and operating profit'!D13="","",'Runway and operating profit'!D13>0))),'Runway and operating profit'!D12/'Runway and operating profit'!D13,"") | E14: =IF(IF(IF(ISERROR('Runway and operating profit'!E13>0),'Runway and operating profit'!E13>0,IF('Runway and operating profit'!E13="","",'Runway and operating profit'!E13>0))="",FALSE,IF(ISERROR('Runway and operating profit'!E13>0),'Runway and operating profit'!E13>0,IF('Runway and operating profit'!E13="","",'Runway and operating profit'!E13>0))),'Runway and operating profit'!E12/'Runway and operating profit'!E13,"") | F14: =IF(IF(IF(ISERROR('Runway and operating profit'!F13>0),'Runway and operating profit'!F13>0,IF('Runway and operating profit'!F13="","",'Runway and operating profit'!F13>0))="",FALSE,IF(ISERROR('Runway and operating profit'!F13>0),'Runway and operating profit'!F13>0,IF('Runway and operating profit'!F13="","",'Runway and operating profit'!F13>0))),'Runway and operating profit'!F12/'Runway and operating profit'!F13,"") | G14: =IF(IF(IF(ISERROR('Runway and operating profit'!G13>0),'Runway and operating profit'!G13>0,IF('Runway and operating profit'!G13="","",'Runway and operating profit'!G13>0))="",FALSE,IF(ISERROR('Runway and operating profit'!G13>0),'Runway and operating profit'!G13>0,IF('Runway and operating profit'!G13="","",'Runway and operating profit'!G13>0))),'Runway and operating profit'!G12/'Runway and operating profit'!G13,"") | H14: =IF(IF(IF(ISERROR('Runway and operating profit'!H13>0),'Runway and operating profit'!H13>0,IF('Runway and operating profit'!H13="","",'Runway and operating profit'!H13>0))="",FALSE,IF(ISERROR('Runway and operating profit'!H13>0),'Runway and operating profit'!H13>0,IF('Runway and operating profit'!H13="","",'Runway and operating profit'!H13>0))),'Runway and operating profit'!H12/'Runway and operating profit'!H13,"") | I14: =IF(IF(IF(ISERROR('Runway and operating profit'!I13>0),'Runway and operating profit'!I13>0,IF('Runway and operating profit'!I13="","",'Runway and operating profit'!I13>0))="",FALSE,IF(ISERROR('Runway and operating profit'!I13>0),'Runway and operating profit'!I13>0,IF('Runway and operating profit'!I13="","",'Runway and operating profit'!I13>0))),'Runway and operating profit'!I12/'Runway and operating profit'!I13,"") | ... M14: =IF(IF(IF(ISERROR('Runway and operating profit'!M13>0),'Runway and operating profit'!M13>0,IF('Runway and operating profit'!M13="","",'Runway and operating profit'!M13>0))="",FALSE,IF(ISERROR('Runway and operating profit'!M13>0),'Runway and operating profit'!M13>0,IF('Runway and operating profit'!M13="","",'Runway and operating profit'!M13>0))),'Runway and operating profit'!M12/'Runway and operating profit'!M13,"")

Sheet Year 1 scenario comparison
A1: Year 1 scenario comparison
A2: NaukriShield — Business Plan · Main Scenario
A4: Variable / dimension | B4: Value | C4: Value > NaukriShield — Downside | D4: Value > NaukriShield — Upside
A5: NS Year 1 revenue | B5: =SUM('Monthly revenue and check costs'!B5,'Monthly revenue and check costs'!C5,'Monthly revenue and check costs'!D5,'Monthly revenue and check costs'!E5,'Monthly revenue and check costs'!F5,'Monthly revenue and check costs'!G5,'Monthly revenue and check costs'!H5,'Monthly revenue and check costs'!I5,'Monthly revenue and check costs'!J5,'Monthly revenue and check costs'!K5,'Monthly revenue and check costs'!L5,'Monthly revenue and check costs'!M5) -> 2667600 | C5: =SUM('Model inputs'!N38,'Model inputs'!O38,'Model inputs'!P38,'Model inputs'!Q38,'Model inputs'!R38,'Model inputs'!S38,'Model inputs'!T38,'Model inputs'!U38,'Model inputs'!V38,'Model inputs'!W38,'Model inputs'!X38,'Model inputs'!Y38) -> 119760 | D5: =SUM('Model inputs'!N37,'Model inputs'!O37,'Model inputs'!P37,'Model inputs'!Q37,'Model inputs'!R37,'Model inputs'!S37,'Model inputs'!T37,'Model inputs'!U37,'Model inputs'!V37,'Model inputs'!W37,'Model inputs'!X37,'Model inputs'!Y37) -> 4736400
A6: NS Year 1 check costs | B6: =SUM('Monthly revenue and check costs'!B13,'Monthly revenue and check costs'!C13,'Monthly revenue and check costs'!D13,'Monthly revenue and check costs'!E13,'Monthly revenue and check costs'!F13,'Monthly revenue and check costs'!G13,'Monthly revenue and check costs'!H13,'Monthly revenue and check costs'!I13,'Monthly revenue and check costs'!J13,'Monthly revenue and check costs'!K13,'Monthly revenue and check costs'!L13,'Monthly revenue and check costs'!M13) -> 202500 | C6: =SUM('Model inputs'!N26,'Model inputs'!O26,'Model inputs'!P26,'Model inputs'!Q26,'Model inputs'!R26,'Model inputs'!S26,'Model inputs'!T26,'Model inputs'!U26,'Model inputs'!V26,'Model inputs'!W26,'Model inputs'!X26,'Model inputs'!Y26) -> 86400 | D6: =SUM('Model inputs'!N25,'Model inputs'!O25,'Model inputs'!P25,'Model inputs'!Q25,'Model inputs'!R25,'Model inputs'!S25,'Model inputs'!T25,'Model inputs'!U25,'Model inputs'!V25,'Model inputs'!W25,'Model inputs'!X25,'Model inputs'!Y25) -> 459000
A7: NS Year 1 gross margin | B7: =IFERROR(('Year 1 scenario comparison'!B5-'Year 1 scenario comparison'!B6)/'Year 1 scenario comparison'!B5,"") -> 0.92408907 | C7: =IFERROR(('Year 1 scenario comparison'!C5-'Year 1 scenario comparison'!C6)/'Year 1 scenario comparison'!C5,"") -> 0.27855711 | D7: =IFERROR(('Year 1 scenario comparison'!D5-'Year 1 scenario comparison'!D6)/'Year 1 scenario comparison'!D5,"") -> 0.90309096
A8: NS Year 1 operating profit | B8: =SUM('Runway and operating profit'!B10,'Runway and operating profit'!C10,'Runway and operating profit'!D10,'Runway and operating profit'!E10,'Runway and operating profit'!F10,'Runway and operating profit'!G10,'Runway and operating profit'!H10,'Runway and operating profit'!I10,'Runway and operating profit'!J10,'Runway and operating profit'!K10,'Runway and operating profit'!L10,'Runway and operating profit'!M10) -> 2288790 | C8: =SUM('Model inputs'!N31,'Model inputs'!O31,'Model inputs'!P31,'Model inputs'!Q31,'Model inputs'!R31,'Model inputs'!S31,'Model inputs'!T31,'Model inputs'!U31,'Model inputs'!V31,'Model inputs'!W31,'Model inputs'!X31,'Model inputs'!Y31) -> -142950 | D8: =SUM('Model inputs'!N30,'Model inputs'!O30,'Model inputs'!P30,'Model inputs'!Q30,'Model inputs'!R30,'Model inputs'!S30,'Model inputs'!T30,'Model inputs'!U30,'Model inputs'!V30,'Model inputs'!W30,'Model inputs'!X30,'Model inputs'!Y30) -> 4101090
A9: NS starting cash runway months | B9: =IF(IF(IF(ISERROR('Year 1 scenario comparison'!B8<0),'Year 1 scenario comparison'!B8<0,IF('Year 1 scenario comparison'!B8="","",'Year 1 scenario comparison'!B8<0))="",FALSE,IF(ISERROR('Year 1 scenario comparison'!B8<0),'Year 1 scenario comparison'!B8<0,IF('Year 1 scenario comparison'!B8="","",'Year 1 scenario comparison'!B8<0))),'Pricing and editable planning i'!B17/(-'Year 1 scenario comparison'!B8/12),"") | C9: =IF(IF(IF(ISERROR('Year 1 scenario comparison'!C8<0),'Year 1 scenario comparison'!C8<0,IF('Year 1 scenario comparison'!C8="","",'Year 1 scenario comparison'!C8<0))="",FALSE,IF(ISERROR('Year 1 scenario comparison'!C8<0),'Year 1 scenario comparison'!C8<0,IF('Year 1 scenario comparison'!C8="","",'Year 1 scenario comparison'!C8<0))),'Model inputs'!B42/(-'Year 1 scenario comparison'!C8/12),"") -> 25.183631 | D9: =IF(IF(IF(ISERROR('Year 1 scenario comparison'!D8<0),'Year 1 scenario comparison'!D8<0,IF('Year 1 scenario comparison'!D8="","",'Year 1 scenario comparison'!D8<0))="",FALSE,IF(ISERROR('Year 1 scenario comparison'!D8<0),'Year 1 scenario comparison'!D8<0,IF('Year 1 scenario comparison'!D8="","",'Year 1 scenario comparison'!D8<0))),'Model inputs'!B41/(-'Year 1 scenario comparison'!D8/12),"")

Sheet Model inputs
A1: Model inputs
A2: Integration values are aggregated snapshots; raw source records are not included.
A4: Variables
A5: Variable / segment | B5: Value | C5: Value | D5: 2026-01 | E5: 2026-02 | F5: 2026-03 | G5: 2026-04 | H5: 2026-05 | I5: 2026-06 | J5: 2026-07 | K5: 2026-08 | L5: 2026-09 | M5: 2026-10 | N5: 2026-11 | O5: 2026-12 | P5: 2027-01 | Q5: 2027-02 | R5: 2027-03 | S5: 2027-04 | T5: 2027-05 | U5: 2027-06 | V5: 2027-07 | W5: 2027-08 | X5: 2027-09 | Y5: 2027-10 | Z5: 2027-11 | AA5: 2027-12
A6: Active free students · Year 1 totals and 45-cafe break-even | B6: ='Pricing and editable planning i'!B14 -> 1000
A7: Active free students · Monthly revenue and check costs | C7: ='Pricing and editable planning i'!B14 -> 1000
A8: API check price · Year 1 totals and 45-cafe break-even | B8: ='Pricing and editable planning i'!B7 -> 49
A9: API check price · Monthly revenue and check costs | C9: ='Pricing and editable planning i'!B7 -> 49
A10: Cafe monthly price · Year 1 totals and 45-cafe break-even | B10: ='Pricing and editable planning i'!B6 -> 499
A11: Cafe monthly price · Monthly revenue and check costs | C11: ='Pricing and editable planning i'!B6 -> 499
A12: Checks per cafe per month · Year 1 totals and 45-cafe break-even | B12: ='Pricing and editable planning i'!B13 -> 10
A13: Checks per cafe per month · Monthly revenue and check costs | C13: ='Pricing and editable planning i'!B13 -> 10
A14: Checks per free student per month · Year 1 totals and 45-cafe break-even | B14: ='Pricing and editable planning i'!B15 -> 3
A15: Checks per free student per month · Monthly revenue and check costs | C15: ='Pricing and editable planning i'!B15 -> 3
A16: Cost per check · Year 1 totals and 45-cafe break-even | B16: ='Model inputs'!B49+'Model inputs'!B48 -> 2.25
A17: Cost per check · Monthly revenue and check costs | C17: ='Model inputs'!B49+'Model inputs'!B48 -> 2.25
A18: Monthly non-check overhead · Year 1 totals and 45-cafe break-even | B18: ='Pricing and editable planning i'!B16 -> 14692.5
A19: Monthly non-check overhead · Runway and operating profit | C19: ='Pricing and editable planning i'!B16 -> 14692.5
A20: NS check costs · by · Year 1 totals and 45-cafe break-even · Main Scenario | D20: =SUM('Model inputs'!D22,'Model inputs'!D23,'Model inputs'!D24) -> 0 | E20: =SUM('Model inputs'!E22,'Model inputs'!E23,'Model inputs'!E24) -> 0 | F20: =SUM('Model inputs'!F22,'Model inputs'!F23,'Model inputs'!F24) -> 0 | G20: =SUM('Model inputs'!G22,'Model inputs'!G23,'Model inputs'!G24) -> 0 | H20: =SUM('Model inputs'!H22,'Model inputs'!H23,'Model inputs'!H24) -> 0 | I20: =SUM('Model inputs'!I22,'Model inputs'!I23,'Model inputs'!I24) -> 0 | J20: =SUM('Model inputs'!J22,'Model inputs'!J23,'Model inputs'!J24) -> 0 | K20: =SUM('Model inputs'!K22,'Model inputs'!K23,'Model inputs'!K24) -> 0 | ... AA20: =SUM('Model inputs'!AA22,'Model inputs'!AA23,'Model inputs'!AA24) -> 16875
A21: NS check costs | D21: =IF('Model inputs'!D20="","",'Model inputs'!D20) -> 0 | E21: =IF('Model inputs'!E20="","",'Model inputs'!E20) -> 0 | F21: =IF('Model inputs'!F20="","",'Model inputs'!F20) -> 0 | G21: =IF('Model inputs'!G20="","",'Model inputs'!G20) -> 0 | H21: =IF('Model inputs'!H20="","",'Model inputs'!H20) -> 0 | I21: =IF('Model inputs'!I20="","",'Model inputs'!I20) -> 0 | J21: =IF('Model inputs'!J20="","",'Model inputs'!J20) -> 0 | K21: =IF('Model inputs'!K20="","",'Model inputs'!K20) -> 0 | ... AA21: =IF('Model inputs'!AA20="","",'Model inputs'!AA20) -> 16875
A22: NS check costs > API | D22: =0 -> 0 | E22: =0 -> 0 | F22: =0 -> 0 | G22: =0 -> 0 | H22: =0 -> 0 | I22: =0 -> 0 | J22: =0 -> 0 | K22: =0 -> 0 | L22: =0 -> 0 | M22: ='Model inputs'!M65*'Model inputs'!B16 -> 5625 | N22: ='Model inputs'!N51*'Model inputs'!B16 -> 5625 | O22: ='Model inputs'!O51*'Model inputs'!B16 -> 5625 | P22: ='Model inputs'!P51*'Model inputs'!B16 -> 5625 | Q22: ='Model inputs'!Q51*'Model inputs'!B16 -> 5625 | R22: ='Model inputs'!R51*'Model inputs'!B16 -> 5625 | S22: ='Model inputs'!S51*'Model inputs'!B16 -> 5625 | T22: ='Model inputs'!T51*'Model inputs'!B16 -> 5625 | U22: ='Model inputs'!U51*'Model inputs'!B16 -> 5625 | V22: ='Model inputs'!V51*'Model inputs'!B16 -> 5625 | W22: ='Model inputs'!W51*'Model inputs'!B16 -> 5625 | X22: ='Model inputs'!X51*'Model inputs'!B16 -> 5625 | Y22: ='Model inputs'!Y51*'Model inputs'!B16 -> 5625 | Z22: ='Model inputs'!Z65*'Model inputs'!B16 -> 5625 | AA22: ='Model inputs'!AA65*'Model inputs'!B16 -> 5625
A23: NS check costs > Cyber-cafes | D23: =0 -> 0 | E23: =0 -> 0 | F23: =0 -> 0 | G23: =0 -> 0 | H23: =0 -> 0 | I23: =0 -> 0 | J23: =0 -> 0 | K23: =0 -> 0 | L23: =0 -> 0 | M23: ='Model inputs'!M66*'Model inputs'!B16 -> 4500 | N23: ='Model inputs'!N52*'Model inputs'!B16 -> 4500 | O23: ='Model inputs'!O52*'Model inputs'!B16 -> 4500 | P23: ='Model inputs'!P52*'Model inputs'!B16 -> 4500 | Q23: ='Model inputs'!Q52*'Model inputs'!B16 -> 4500 | R23: ='Model inputs'!R52*'Model inputs'!B16 -> 4500 | S23: ='Model inputs'!S52*'Model inputs'!B16 -> 4500 | T23: ='Model inputs'!T52*'Model inputs'!B16 -> 4500 | U23: ='Model inputs'!U52*'Model inputs'!B16 -> 4500 | V23: ='Model inputs'!V52*'Model inputs'!B16 -> 4500 | W23: ='Model inputs'!W52*'Model inputs'!B16 -> 4500 | X23: ='Model inputs'!X52*'Model inputs'!B16 -> 4500 | Y23: ='Model inputs'!Y52*'Model inputs'!B16 -> 4500 | Z23: ='Model inputs'!Z66*'Model inputs'!B16 -> 4500 | AA23: ='Model inputs'!AA66*'Model inputs'!B16 -> 4500
A24: NS check costs > Students | D24: =0 -> 0 | E24: =0 -> 0 | F24: =0 -> 0 | G24: =0 -> 0 | H24: =0 -> 0 | I24: =0 -> 0 | J24: =0 -> 0 | K24: =0 -> 0 | L24: =0 -> 0 | M24: ='Model inputs'!M67*'Model inputs'!B16 -> 6750 | N24: ='Model inputs'!N53*'Model inputs'!B16 -> 6750 | O24: ='Model inputs'!O53*'Model inputs'!B16 -> 6750 | P24: ='Model inputs'!P53*'Model inputs'!B16 -> 6750 | Q24: ='Model inputs'!Q53*'Model inputs'!B16 -> 6750 | R24: ='Model inputs'!R53*'Model inputs'!B16 -> 6750 | S24: ='Model inputs'!S53*'Model inputs'!B16 -> 6750 | T24: ='Model inputs'!T53*'Model inputs'!B16 -> 6750 | U24: ='Model inputs'!U53*'Model inputs'!B16 -> 6750 | V24: ='Model inputs'!V53*'Model inputs'!B16 -> 6750 | W24: ='Model inputs'!W53*'Model inputs'!B16 -> 6750 | X24: ='Model inputs'!X53*'Model inputs'!B16 -> 6750 | Y24: ='Model inputs'!Y53*'Model inputs'!B16 -> 6750 | Z24: ='Model inputs'!Z67*'Model inputs'!B16 -> 6750 | AA24: ='Model inputs'!AA67*'Model inputs'!B16 -> 6750
A25: NS check costs · NaukriShield — Upside | D25: =SUM('Model inputs'!D57,'Model inputs'!D58,'Model inputs'!D59) -> 0 | E25: =SUM('Model inputs'!E57,'Model inputs'!E58,'Model inputs'!E59) -> 0 | F25: =SUM('Model inputs'!F57,'Model inputs'!F58,'Model inputs'!F59) -> 0 | G25: =SUM('Model inputs'!G57,'Model inputs'!G58,'Model inputs'!G59) -> 0 | H25: =SUM('Model inputs'!H57,'Model inputs'!H58,'Model inputs'!H59) -> 0 | I25: =SUM('Model inputs'!I57,'Model inputs'!I58,'Model inputs'!I59) -> 0 | J25: =SUM('Model inputs'!J57,'Model inputs'!J58,'Model inputs'!J59) -> 0 | K25: =SUM('Model inputs'!K57,'Model inputs'!K58,'Model inputs'!K59) -> 0 | ... AA25: =SUM('Model inputs'!AA57,'Model inputs'!AA58,'Model inputs'!AA59) -> 38250
A26: NS check costs · NaukriShield — Downside | D26: =SUM('Model inputs'!D61,'Model inputs'!D62,'Model inputs'!D63) -> 0 | E26: =SUM('Model inputs'!E61,'Model inputs'!E62,'Model inputs'!E63) -> 0 | F26: =SUM('Model inputs'!F61,'Model inputs'!F62,'Model inputs'!F63) -> 0 | G26: =SUM('Model inputs'!G61,'Model inputs'!G62,'Model inputs'!G63) -> 0 | H26: =SUM('Model inputs'!H61,'Model inputs'!H62,'Model inputs'!H63) -> 0 | I26: =SUM('Model inputs'!I61,'Model inputs'!I62,'Model inputs'!I63) -> 0 | J26: =SUM('Model inputs'!J61,'Model inputs'!J62,'Model inputs'!J63) -> 0 | K26: =SUM('Model inputs'!K61,'Model inputs'!K62,'Model inputs'!K63) -> 0 | ... AA26: =SUM('Model inputs'!AA61,'Model inputs'!AA62,'Model inputs'!AA63) -> 7200
A27: NS closing cash | K27: 0 | L27: 0 | M27: ='Model inputs'!M28+'Model inputs'!M29 -> 190732.5 | N27: ='Model inputs'!N28+'Model inputs'!N29 -> 490732.5 | O27: ='Model inputs'!O28+'Model inputs'!O29 -> 681465 | P27: ='Model inputs'!P28+'Model inputs'!P29 -> 872197.5 | Q27: ='Model inputs'!Q28+'Model inputs'!Q29 -> 1062930 | R27: ='Model inputs'!R28+'Model inputs'!R29 -> 1253662.5 | S27: ='Model inputs'!S28+'Model inputs'!S29 -> 1444395 | T27: ='Model inputs'!T28+'Model inputs'!T29 -> 1635127.5 | ... Y27: ='Model inputs'!Y28+'Model inputs'!Y29 -> 2588790
A28: NS opening cash | L28: 0 | M28: =IF('Model inputs'!L27="","",'Model inputs'!L27) -> 0 | N28: =IF('Model inputs'!B39="","",'Model inputs'!B39) -> 300000 | O28: =IF('Model inputs'!N27="","",'Model inputs'!N27) -> 490732.5 | P28: =IF('Model inputs'!O27="","",'Model inputs'!O27) -> 681465 | Q28: =IF('Model inputs'!P27="","",'Model inputs'!P27) -> 872197.5 | R28: =IF('Model inputs'!Q27="","",'Model inputs'!Q27) -> 1062930 | S28: =IF('Model inputs'!R27="","",'Model inputs'!R27) -> 1253662.5 | T28: =IF('Model inputs'!S27="","",'Model inputs'!S27) -> 1444395 | U28: =IF('Model inputs'!T27="","",'Model inputs'!T27) -> 1635127.5 | V28: =IF('Model inputs'!U27="","",'Model inputs'!U27) -> 1825860 | ... Y28: =IF('Model inputs'!X27="","",'Model inputs'!X27) -> 2398057.5
A29: NS operating profit · Year 1 totals and 45-cafe break-even · Main Scenario | D29: 0 | E29: 0 | F29: 0 | G29: 0 | H29: 0 | I29: 0 | J29: 0 | K29: 0 | L29: 0 | M29: ='Model inputs'!M54-'Model inputs'!M55 -> 190732.5 | N29: ='Model inputs'!N54-'Model inputs'!N55 -> 190732.5 | O29: ='Model inputs'!O54-'Model inputs'!O55 -> 190732.5 | P29: ='Model inputs'!P54-'Model inputs'!P55 -> 190732.5 | Q29: ='Model inputs'!Q54-'Model inputs'!Q55 -> 190732.5 | R29: ='Model inputs'!R54-'Model inputs'!R55 -> 190732.5 | S29: ='Model inputs'!S54-'Model inputs'!S55 -> 190732.5 | T29: ='Model inputs'!T54-'Model inputs'!T55 -> 190732.5 | ... Y29: ='Model inputs'!Y54-'Model inputs'!Y55 -> 190732.5 | Z29: ='Model inputs'!Z68-'Model inputs'!Z71 -> 190732.5 | AA29: ='Model inputs'!AA68-'Model inputs'!AA71 -> 190732.5
